<?xml version="1.0" encoding="UTF-8"?>
<testng-results total="1" passed="0" failed="1" skipped="0">
  <reporter-output>
  </reporter-output>
  <suite started-at="2022-02-13T16:01:53Z" name="Default suite" finished-at="2022-02-13T16:02:03Z" duration-ms="9776">
    <groups>
    </groups>
    <test started-at="2022-02-13T16:01:53Z" name="Default test" finished-at="2022-02-13T16:02:03Z" duration-ms="9776">
      <class name="base.calculateTest">
        <test-method is-config="true" signature="Setup()[pri:0, instance:base.calculateTest@59505b48]" started-at="2022-02-13T22:01:47Z" name="Setup" finished-at="2022-02-13T22:01:53Z" duration-ms="5899" status="PASS">
          <reporter-output>
          </reporter-output>
        </test-method> <!-- Setup -->
        <test-method signature="getvalidResult()[pri:0, instance:base.calculateTest@59505b48]" started-at="2022-02-13T22:01:53Z" name="getvalidResult" finished-at="2022-02-13T22:02:03Z" duration-ms="9752" status="FAIL">
          <exception class="java.lang.AssertionError">
            <message>
              <![CDATA[expected [4] but found [3]]]>
            </message>
            <full-stacktrace>
              <![CDATA[java.lang.AssertionError: expected [4] but found [3]
	at org.testng.Assert.fail(Assert.java:94)
	at org.testng.Assert.failNotEquals(Assert.java:513)
	at org.testng.Assert.assertEqualsImpl(Assert.java:135)
	at org.testng.Assert.assertEquals(Assert.java:116)
	at org.testng.Assert.assertEquals(Assert.java:190)
	at org.testng.Assert.assertEquals(Assert.java:200)
	at base.calculateTest.getvalidResult(calculateTest.java:20)
	at java.base/jdk.internal.reflect.NativeMethodAccessorImpl.invoke0(Native Method)
	at java.base/jdk.internal.reflect.NativeMethodAccessorImpl.invoke(NativeMethodAccessorImpl.java:64)
	at java.base/jdk.internal.reflect.DelegatingMethodAccessorImpl.invoke(DelegatingMethodAccessorImpl.java:43)
	at java.base/java.lang.reflect.Method.invoke(Method.java:564)
	at org.testng.internal.MethodInvocationHelper.invokeMethod(MethodInvocationHelper.java:86)
	at org.testng.internal.Invoker.invokeMethod(Invoker.java:643)
	at org.testng.internal.Invoker.invokeTestMethod(Invoker.java:820)
	at org.testng.internal.Invoker.invokeTestMethods(Invoker.java:1128)
	at org.testng.internal.TestMethodWorker.invokeTestMethods(TestMethodWorker.java:129)
	at org.testng.internal.TestMethodWorker.run(TestMethodWorker.java:112)
	at org.testng.TestRunner.privateRun(TestRunner.java:782)
	at org.testng.TestRunner.run(TestRunner.java:632)
	at org.testng.SuiteRunner.runTest(SuiteRunner.java:366)
	at org.testng.SuiteRunner.runSequentially(SuiteRunner.java:361)
	at org.testng.SuiteRunner.privateRun(SuiteRunner.java:319)
	at org.testng.SuiteRunner.run(SuiteRunner.java:268)
	at org.testng.SuiteRunnerWorker.runSuite(SuiteRunnerWorker.java:52)
	at org.testng.SuiteRunnerWorker.run(SuiteRunnerWorker.java:86)
	at org.testng.TestNG.runSuitesSequentially(TestNG.java:1244)
	at org.testng.TestNG.runSuitesLocally(TestNG.java:1169)
	at org.testng.TestNG.run(TestNG.java:1064)
	at org.testng.remote.AbstractRemoteTestNG.run(AbstractRemoteTestNG.java:115)
	at org.testng.remote.RemoteTestNG.initAndRun(RemoteTestNG.java:251)
	at org.testng.remote.RemoteTestNG.main(RemoteTestNG.java:77)
]]>
            </full-stacktrace>
          </exception> <!-- java.lang.AssertionError -->
          <reporter-output>
          </reporter-output>
        </test-method> <!-- getvalidResult -->
        <test-method is-config="true" signature="tearDown()[pri:0, instance:base.calculateTest@59505b48]" started-at="2022-02-13T22:02:03Z" name="tearDown" finished-at="2022-02-13T22:02:04Z" duration-ms="437" status="PASS">
          <reporter-output>
          </reporter-output>
        </test-method> <!-- tearDown -->
      </class> <!-- base.calculateTest -->
    </test> <!-- Default test -->
  </suite> <!-- Default suite -->
</testng-results>
